<?xml version="1.0" ?>
<!-- =================================================================================== -->
<!-- |    This document was autogenerated by xacro from robot_x.xacro                  | -->
<!-- |    EDITING THIS FILE BY HAND IS NOT RECOMMENDED                                 | -->
<!-- =================================================================================== -->
<robot name="Robot" xmlns:xacro="http://www.ros.org/wiki/xacro">
  <!--=======================XACRO DEFINE==============================!-->
  <!--=======================LINK DEFINE==============================!-->
  <link name="base_link">
    <visual>
      <geometry>
        <box size="0.2 .3 0.1"/>
      </geometry>
      <origin rpy="0 0 0" xyz="0 0 0"/>
      <material name="white">
        <color rgba="1 1 1 1"/>
      </material>
    </visual>
  </link>
  <link name="upper_link">
    <visual>
      <geometry>
        <box size="0.05 .3 .1"/>
      </geometry>
      <origin rpy="0 0 0" xyz="0.0866 0 0.05"/>
      <material name="brown">
        <color rgba="0.5 0.4 0.2 1"/>
      </material>
    </visual>
    <visual>
      <geometry>
        <box size="0.05 .3 .1"/>
      </geometry>
      <origin rpy="0 0 -1.04719733333" xyz="-0.0433 0.075 0.05"/>
      <material name="brown">
        <color rgba="0.5 0.4 0.2 1"/>
      </material>
    </visual>
    <visual>
      <geometry>
        <box size="0.05 .3 .1"/>
      </geometry>
      <origin rpy="0 0 1.04719733333" xyz="-0.0433 -0.075 0.05"/>
      <material name="brown">
        <color rgba="0.5 0.4 0.2 1"/>
      </material>
    </visual>
  </link>
  <link name="kinect">
    <visual>
      <geometry>
        <box size="0.08 .2 0.08"/>
      </geometry>
      <origin xyz="0 0 0"/>
      <material name="black">
        <color rgba="0 0 0 1"/>
      </material>
    </visual>
  </link>
  <link name="wheel_1">
    <visual>
      <geometry>
        <cylinder length="0.04" radius="0.065"/>
      </geometry>
      <origin rpy="0 0 0" xyz="0 0 0.07"/>
      <material name="black">
        <color rgba="0 0 0 1"/>
      </material>
    </visual>
  </link>
  <link name="wheel_2">
    <visual>
      <geometry>
        <cylinder length="0.04" radius="0.065"/>
      </geometry>
      <origin rpy="0 0 0" xyz="0 0 0.07"/>
      <material name="black">
        <color rgba="0 0 0 1"/>
      </material>
    </visual>
  </link>
  <!--=======================JOINT DEFINE==============================!-->
  <joint name="B2U" type="revolute">
    <parent link="base_link"/>
    <child link="upper_link"/>
    <origin rpy="0 0 -1.570796" xyz="0 0 0.055"/>
    <axis xyz="0 0 1"/>
    <limit effort="1000.0" lower="-3.141592" upper="3.141592" velocity="0.5"/>
  </joint>
  <joint name="U2K" type="fixed">
    <parent link="upper_link"/>
    <child link="kinect"/>
    <origin rpy="0 0 0" xyz="0.0866 0 0.05"/>
  </joint>
  <joint name="B2W1" type="continuous">
    <parent link="base_link"/>
    <child link="wheel_1"/>
    <origin rpy="0 1.570796 0" xyz="0.05 0 -0.06"/>
    <axis xyz="0 0 1"/>
  </joint>
  <joint name="B2W2" type="continuous">
    <parent link="base_link"/>
    <child link="wheel_2"/>
    <origin rpy="0 -1.570796 0" xyz="-0.05 0 -0.06"/>
    <axis xyz="0 0 1"/>
  </joint>
</robot>

