<?xml version="1.0" ?>
<!-- =================================================================================== -->
<!-- |    This document was autogenerated by xacro from ./urdf/robot_x.xacro           | -->
<!-- |    EDITING THIS FILE BY HAND IS NOT RECOMMENDED                                 | -->
<!-- =================================================================================== -->
<robot name="Robot" xmlns:xacro="http://www.ros.org/wiki/xacro">
  <!--=======================XACRO DEFINE==============================!-->
  <!--=======================LINK DEFINE==============================!-->
  <link name="base_link">
    <visual>
      <geometry>
        <box size="0.400 .300 0.086"/>
      </geometry>
      <origin rpy="0 0 0" xyz="0 0 0"/>
      <material name="white">
        <color rgba="1 1 1 1"/>
      </material>
    </visual>
  </link>
  <link name="upper_link">
    <visual>
      <geometry>
        <box size=".080 0.340 0.065"/>
      </geometry>
      <origin rpy="0 0 0" xyz=".140 0 0.0325"/>
      <material name="brown">
        <color rgba="0.5 0.4 0.2 1"/>
      </material>
    </visual>
    <visual>
      <geometry>
        <box size=".080 0.340 0.065"/>
      </geometry>
      <origin rpy="0 0 0" xyz="-0.140 0 0.0325"/>
      <material name="brown">
        <color rgba="0.5 0.4 0.2 1"/>
      </material>
    </visual>
    <visual>
      <geometry>
        <box size="0.200 .200 0.065"/>
      </geometry>
      <origin rpy="0 0 0" xyz="0 0 0.0325"/>
      <material name="brown">
        <color rgba="0.5 0.4 0.2 1"/>
      </material>
    </visual>
  </link>
  <link name="kinect">
    <visual>
      <geometry>
        <box size="0.1 .2 0.045"/>
      </geometry>
      <origin xyz="0 0 0"/>
      <material name="black">
        <color rgba="0 0 0 1"/>
      </material>
    </visual>
  </link>
  <link name="wheel_1">
    <visual>
      <geometry>
        <cylinder length="0.04" radius="0.0635"/>
      </geometry>
      <origin rpy="0 0 0" xyz="0 0 0.1145"/>
      <material name="black">
        <color rgba="0 0 0 1"/>
      </material>
    </visual>
  </link>
  <link name="wheel_2">
    s
			
    <visual>
      <geometry>
        <cylinder length="0.04" radius="0.0635"/>
      </geometry>
      <origin rpy="0 0 0" xyz="0 0 0.1145"/>
      <material name="black">
        <color rgba="0 0 0 1"/>
      </material>
    </visual>
  </link>
  <!--=======================JOINT DEFINE==============================!-->
  <joint name="B2U" type="revolute">
    <parent link="base_link"/>
    <child link="upper_link"/>
    <origin rpy="0 0 0" xyz="0 0 0.08109"/>
    <axis xyz="0 0 1"/>
    <limit effort="1000.0" lower="-3.141592" upper="3.141592" velocity="0.5"/>
  </joint>
  <joint name="U2K" type="fixed">
    <parent link="upper_link"/>
    <child link="kinect"/>
    <origin rpy="0 0 0" xyz="0.140 0 0.0325"/>
  </joint>
  <joint name="B2W1" type="continuous">
    <parent link="base_link"/>
    <child link="wheel_1"/>
    <origin rpy="0 1.570796 1.570796" xyz="0 0.07788 -0.0735"/>
    <axis xyz="0 0 1"/>
  </joint>
  <joint name="B2W2" type="continuous">
    <parent link="base_link"/>
    <child link="wheel_2"/>
    <origin rpy="3.141592 1.570796 1.570796" xyz="0 -0.07788 -0.0735"/>
    <axis xyz="0 0 1"/>
  </joint>
</robot>

